Workbook

Sheet Cover Page
C11: DCF Model
C13: Table of Contents
C15: DCF Model
C16: 3-Statement Model

Sheet DCF Model
B1: In Millions Of $
B3: DCF Model
B5: Assumptions
B6: Tax Rate | D6: =' 3-Statement Model'!$M$14 -> 0.16806955
B7: Discount Rate | D7: 0.09
B8: Perpetural Growth Rate | D8: 0.025
B9: EV/EBITDA Mulltiple | D9: 20.0x
B10: Transaction Date | D10: 45838
B11: Fiscal Year End | D11: 45838
B12: Current Price | D12: 384.41
B13: Shares Outstanding | D13: 7465
B14: Debt | D14: =' 3-Statement Model'!H51 -> 60588
B15: Cash | D15: =' 3-Statement Model'!H43 -> 30242
B16: Capex | D16: =' 3-Statement Model'!M18 -> -40255.25
B18: Discounted Cash Flow | D18: Entry | E18: =2026 -> 2026 | F18: =E18+1 -> 2027 | G18: =F18+1 -> 2028 | H18: =G18+1 -> 2029 | I18: =H18+1 -> 2030 | J18: Exit
B19: Date | D19: 45838 | E19: =D19+365 -> 46203 | F19: =E19+365 -> 46568 | G19: =F19+366 -> 46934 | H19: =G19+365 -> 47299 | I19: =H19+365 -> 47664 | J19: =I19 -> 47664 | L19: Terminal Value
B20: EBIT | D20: - | E20: =' 3-Statement Model'!I34 -> 140028.13 | F20: =' 3-Statement Model'!J34 -> 157524.24 | G20: =' 3-Statement Model'!K34 -> 177206.45 | H20: =' 3-Statement Model'!L34 -> 199347.89 | I20: =' 3-Statement Model'!M34 -> 224255.84 | J20: - | L20: Perpetual Growth | N20: =((I25)*(1+$D$8)/($D$7-$D$8)) -> 2751771.4
B21: Less: Cash Taxes | D21: - | E21: =E20*$D$6 -> 23534.464 | F21: =F20*$D$6 -> 26475.029 | G21: =G20*$D$6 -> 29783.008 | H21: =H20*$D$6 -> 33504.31 | I21: =I20*$D$6 -> 37690.579 | J21: - | L21: Average | N21: =AVERAGE(N20,N22) -> 3995349.9
B22: Plus: D&A | D22: - | E22: =' 3-Statement Model'!I66 -> 33550.679 | F22: =' 3-Statement Model'!J66 -> 34529.589 | G22: =' 3-Statement Model'!K66 -> 35365.573 | H22: =' 3-Statement Model'!L66 -> 36079.497 | I22: =' 3-Statement Model'!M66 -> 36689.184 | J22: - | L22: EV/EBITDA | N22: =((I20+I21)*20) -> 5238928.5
B23: Less: Capex | D23: - | E23: =ABS(' 3-Statement Model'!I72) -> 40255.25 | F23: =ABS(' 3-Statement Model'!J72) -> 40255.25 | G23: =ABS(' 3-Statement Model'!K72) -> 40255.25 | H23: =ABS(' 3-Statement Model'!L72) -> 40255.25 | I23: =ABS(' 3-Statement Model'!M72) -> 40255.25 | J23: -
B24: Less: Changes in NWC | D24: - | E24: =' 3-Statement Model'!I92 -> 4647.5138 | F24: =' 3-Statement Model'!J92 -> 5968.2902 | G24: =' 3-Statement Model'!K92 -> 6714.0111 | H24: =' 3-Statement Model'!L92 -> 7552.9077 | I24: =' 3-Statement Model'!M92 -> 8496.6221 | J24: -
B25: Unlevered FCF | D25: - | E25: =((E20)-(E21)+(E22)-(E23)-(E24)) -> 105141.58 | F25: =((F20)-(F21)+(F22)-(F23)-(F24)) -> 119355.26 | G25: =((G20)-(G21)+(G22)-(G23)-(G24)) -> 135819.75 | H25: =((H20)-(H21)+(H22)-(H23)-(H24)) -> 154114.92 | I25: =((I20)-(I21)+(I22)-(I23)-(I24)) -> 174502.58 | J25: -
B26: (Entry)/Exit | D26: =-I34 -> -2899966.7 | J26: =N21 -> 3995349.9
B27: Transaction CF | D27: =D26 -> -2899966.7 | E27: =E25 -> 105141.58 | F27: =F25 -> 119355.26 | G27: =G25 -> 135819.75 | H27: =H25 -> 154114.92 | I27: =I25 -> 174502.58 | J27: =I27+J26 -> 4169852.5
B30: Intrinsic Value | G30: Market Value | L30: Rate of Return
B31: Enterprise Value | D31: =E25/(1+$D$7)^1+F25/(1+$D$7)^2+G25/(1+$D$7)^3+H25/(1+$D$7)^4+I25/(1+$D$7)^5+J26/(1+$D$7)^5 -> 3121093.8 | G31: Market Cap | I31: =D13*D12 -> 2869620.7 | L31: Target Price Upside | N31: =(N37/N35-1) -> 0.077057969
B32: Plus: Cash | D32: =+D15 -> 30242 | G32: Plus: Debt | I32: =D14 -> 60588 | L32: Internal Rate of Return (IRR) | N32: =IRR(D27:J27) -> 0.097473146
B33: Less: Debt | D33: =+D14 -> 60588 | G33: Less: Cash | I33: =+D15 -> 30242
B34: Equity Value | D34: =D31+D32-D33 -> 3090747.8 | G34: Enterprise Value | I34: =I31+I32-I33 -> 2899966.7 | L34: Market Value vs Intrinsic Value
L35: Market Value | N35: =I36 -> 384.41
B36: Equity Value/Share | D36: =D34/D13 -> 414.03185 | G36: Equity Value/Share | I36: =D12 -> 384.41 | L36: Upside | N36: =N37/N35-1 -> 0.077057969
L37: Intrinsic Value | N37: =D36 -> 414.03185

Sheet  3-Statement Model
D1: Historical Results | I1: Forecast Period
A2: In Millions of US $ | D2: 2021 | E2: =+D2+1 -> 2022 | F2: =+E2+1 -> 2023 | G2: =+F2+1 -> 2024 | H2: =+G2+1 -> 2025 | I2: =+H2+1 -> 2026 | J2: =+I2+1 -> 2027 | K2: =+J2+1 -> 2028 | L2: =+K2+1 -> 2029 | M2: =+L2+1 -> 2030
A5: Assumptions
A7: Key Assumptions
A8: Revenue Growth (% Change) | D8: - | E8: - | F8: =(F26/E26)-1 -> 0.068820296 | G8: =(G26/F26)-1 -> 0.15669962 | H8: =(H26/G26)-1 -> 0.14932156 | I8: =AVERAGE($F$8:$H$8) -> 0.12494716 | J8: =AVERAGE($F$8:$H$8) -> 0.12494716 | K8: =AVERAGE($F$8:$H$8) -> 0.12494716 | L8: =AVERAGE($F$8:$H$8) -> 0.12494716 | M8: =AVERAGE($F$8:$H$8) -> 0.12494716
A9: Cost of Goods Sold (% of Revenue) | D9: - | E9: =E27/E26 -> 0.31598326 | F9: =F27/F26 -> 0.31079914 | G9: =G27/G26 -> 0.30235556 | H9: =H27/H26 -> 0.31176258 | I9: =AVERAGE($E$9:$H$9) -> 0.31022513 | J9: =AVERAGE($E$9:$H$9) -> 0.31022513 | K9: =AVERAGE($E$9:$H$9) -> 0.31022513 | L9: =AVERAGE($E$9:$H$9) -> 0.31022513 | M9: =AVERAGE($E$9:$H$9) -> 0.31022513
A10: Salaries and Benefits (% of Revenue) | D10: - | E10: =E31/E26 -> 0.13983457 | F10: =F31/F26 -> 0.1431423 | G10: =G31/G26 -> 0.13081241 | H10: =H31/H26 -> 0.11669932 | I10: =AVERAGE($E$10:$H$10) -> 0.13262215 | J10: =AVERAGE($E$10:$H$10) -> 0.13262215 | K10: =AVERAGE($E$10:$H$10) -> 0.13262215 | L10: =AVERAGE($E$10:$H$10) -> 0.13262215 | M10: =AVERAGE($E$10:$H$10) -> 0.13262215
A11: Rent and Overhead ($000's) | D11: - | E11: 0 | F11: 0 | G11: 0 | H11: 0 | I11: =H11 -> 0 | J11: =I11 -> 0 | K11: =J11 -> 0 | L11: =K11 -> 0 | M11: =L11 -> 0
A12: Depreciation & Amortization (% of PP&E) | D12: - | E12: =E66/E46 -> 0.16517031 | F12: =F66/F46 -> 0.12602398 | G12: =G66/G46 -> 0.14420389 | H12: =H66/H46 -> 0.14862765 | I12: =AVERAGE($E$12:$H$12) -> 0.14600646 | J12: =AVERAGE($E$12:$H$12) -> 0.14600646 | K12: =AVERAGE($E$12:$H$12) -> 0.14600646 | L12: =AVERAGE($E$12:$H$12) -> 0.14600646 | M12: =AVERAGE($E$12:$H$12) -> 0.14600646
A13: Interest (% of Debt) | D13: - | E13: 0 | F13: 0 | G13: 0 | H13: 0 | I13: =H13 -> 0 | J13: =I13 -> 0 | K13: =J13 -> 0 | L13: =K13 -> 0 | M13: =L13 -> 0
A14: Tax Rate (% of Earnings Before Tax) | D14: - | E14: =E36/E34 -> 0.13165753 | F14: =F36/F34 -> 0.19147566 | G14: =G36/G34 -> 0.17957106 | H14: =H36/H34 -> 0.16957394 | I14: =AVERAGE($E$14:$H$14) -> 0.16806955 | J14: =AVERAGE($E$14:$H$14) -> 0.16806955 | K14: =AVERAGE($E$14:$H$14) -> 0.16806955 | L14: =AVERAGE($E$14:$H$14) -> 0.16806955 | M14: =AVERAGE($E$14:$H$14) -> 0.16806955
A15: Accounts Receivable (Days) | D15: - | E15: =((E44/E26)*365) -> 81.481137 | F15: =((F44/F26)*365) -> 83.859661 | G15: =((G44/G26)*365) -> 84.762934 | H15: =((H44/H26)*365) -> 90.568517 | I15: =AVERAGE($E$15:$H$15) -> 85.168062 | J15: =AVERAGE($E$15:$H$15) -> 85.168062 | K15: =AVERAGE($E$15:$H$15) -> 85.168062 | L15: =AVERAGE($E$15:$H$15) -> 85.168062 | M15: =AVERAGE($E$15:$H$15) -> 85.168062
A16: Inventory (Days) | D16: - | E16: =((E45/E27)*365) -> 21.800958 | F16: =((F45/F27)*365) -> 13.854516 | G16: =((G45/G27)*365) -> 6.1363575 | H16: =((H45/H27)*365) -> 3.8980542 | I16: =AVERAGE($E$16:$H$16) -> 11.422471 | J16: =AVERAGE($E$16:$H$16) -> 11.422471 | K16: =AVERAGE($E$16:$H$16) -> 11.422471 | L16: =AVERAGE($E$16:$H$16) -> 11.422471 | M16: =AVERAGE($E$16:$H$16) -> 11.422471
A17: Accounts Payable (Days) | D17: - | E17: =(E50/E27)*365 -> 110.69433 | F17: =(F50/F27)*365 -> 100.27899 | G17: =(G50/G27)*365 -> 108.3269 | H17: =(H50/H27)*365 -> 115.21285 | I17: =AVERAGE($E$17:$H$17) -> 108.62827 | J17: =AVERAGE($E$17:$H$17) -> 108.62827 | K17: =AVERAGE($E$17:$H$17) -> 108.62827 | L17: =AVERAGE($E$17:$H$17) -> 108.62827 | M17: =AVERAGE($E$17:$H$17) -> 108.62827
A18: Capital Expenditures ($000's) | D18: - | E18: =E71 -> -23886 | F18: =F71 -> -28107 | G18: =G71 -> -44477 | H18: =H71 -> -64551 | I18: =AVERAGE($E$18:$H$18) -> -40255.25 | J18: =AVERAGE($E$18:$H$18) -> -40255.25 | K18: =AVERAGE($E$18:$H$18) -> -40255.25 | L18: =AVERAGE($E$18:$H$18) -> -40255.25 | M18: =AVERAGE($E$18:$H$18) -> -40255.25
A19: Debt Issuance (Repayment) ($000's) | D19: - | E19: =E75 -> -9023 | F19: =F75 -> -2750 | G19: =G75 -> -4675 | H19: =H75 -> -3216 | I19: =AVERAGE($E$19:$H$19) -> -4916 | J19: =AVERAGE($E$19:$H$19) -> -4916 | K19: =AVERAGE($E$19:$H$19) -> -4916 | L19: =AVERAGE($E$19:$H$19) -> -4916 | M19: =AVERAGE($E$19:$H$19) -> -4916
A20: Equity Issued (Repaid) ($000's) | D20: - | E20: =E76 -> -30855 | F20: =F76 -> -20379 | G20: =G76 -> -15252 | H20: =H76 -> -16364 | I20: =AVERAGE($E$20:$H$20) -> -20712.5 | J20: =AVERAGE($E$20:$H$20) -> -20712.5 | K20: =AVERAGE($E$20:$H$20) -> -20712.5 | L20: =AVERAGE($E$20:$H$20) -> -20712.5 | M20: =AVERAGE($E$20:$H$20) -> -20712.5
A21: Days in Period | D21: - | E21: 365 | F21: 365 | G21: 365 | H21: 365 | I21: =AVERAGE(E21:H21) -> 365 | J21: =AVERAGE(F21:I21) -> 365 | K21: =AVERAGE(G21:J21) -> 365 | L21: =AVERAGE(H21:K21) -> 365 | M21: =AVERAGE(I21:L21) -> 365
A24: Income Statement
A26: Revenue | D26: - | E26: 198270 | F26: 211915 | G26: 245122 | H26: 281724 | I26: =((H26)*(1+I8)) -> 316924.61 | J26: =((I26)*(1+J8)) -> 356523.44 | K26: =((J26)*(1+K8)) -> 401070.04 | L26: =((K26)*(1+L8)) -> 451182.6 | M26: =((L26)*(1+M8)) -> 507556.58
A27: Cost of Goods Sold (COGS) | D27: - | E27: 62650 | F27: 65863 | G27: 74114 | H27: 87831 | I27: =((I26)*I9) -> 98317.981 | J27: =((J26)*J9) -> 110602.53 | K27: =((K26)*K9) -> 124422.01 | L27: =((L26)*L9) -> 139968.18 | M27: =((M26)*M9) -> 157456.81
A28: Gross Profit | D28: - | E28: 135620 | F28: 146052 | G28: 171008 | H28: 193893 | I28: =I26-I27 -> 218606.63 | J28: =J26-J27 -> 245920.91 | K28: =K26-K27 -> 276648.03 | L28: =L26-L27 -> 311214.42 | M28: =M26-M27 -> 350099.77
A29: Expenses | D29: -
A30: Research and Development Expenses | D30: - | E30: 24512 | F30: 27195 | G30: 29510 | H30: 32488 | I30: =((H30*(1+I8))) -> 36547.283 | J30: =((I30*(1+J8))) -> 41113.763 | K30: =((J30*(1+K8))) -> 46250.81 | L30: =((K30*(1+L8))) -> 52029.718 | M30: =((L30*(1+M8))) -> 58530.683
A31: SG&A Expenses | D31: - | E31: 27725 | F31: 30334 | G31: 32065 | H31: 32877 | I31: =((I26)*(I10)) -> 42031.224 | J31: =((J26)*(J10)) -> 47282.906 | K31: =((K26)*(K10)) -> 53190.77 | L31: =((L26)*(L10)) -> 59836.806 | M31: =((M26)*(M10)) -> 67313.245
A32: Other Operating Income or Expenses | D32: - | E32: - | F32: - | G32: - | H32: - | I32: - | J32: - | K32: - | L32: - | M32: -
A33: Total Expenses | D33: - | E33: =SUM(E30,E31,E32) -> 52237 | F33: =SUM(F30,F31,F32) -> 57529 | G33: =SUM(G30,G31,G32) -> 61575 | H33: =SUM(H30,H31,H32) -> 65365 | I33: =SUM(I30,I31,I32) -> 78578.507 | J33: =SUM(J30,J31,J32) -> 88396.668 | K33: =SUM(K30,K31,K32) -> 99441.581 | L33: =SUM(L30,L31,L32) -> 111866.52 | M33: =SUM(M30,M31,M32) -> 125843.93
A34: Earnings Before Tax | D34: - | E34: =(E28-E33) -> 83383 | F34: =(F28-F33) -> 88523 | G34: =(G28-G33) -> 109433 | H34: =(H28-H33) -> 128528 | I34: =(I28-I33) -> 140028.13 | J34: =(J28-J33) -> 157524.24 | K34: =(K28-K33) -> 177206.45 | L34: =(L28-L33) -> 199347.89 | M34: =(M28-M33) -> 224255.84
A36: Taxes | D36: - | E36: 10978 | F36: 16950 | G36: 19651 | H36: 21795 | I36: =((I34*I14)) -> 23534.464 | J36: =((J34*J14)) -> 26475.029 | K36: =((K34*K14)) -> 29783.008 | L36: =((L34*L14)) -> 33504.31 | M36: =((M34*M14)) -> 37690.579
A37: Net Earnings | D37: - | E37: =E34-E36 -> 72405 | F37: =F34-F36 -> 71573 | G37: =G34-G36 -> 89782 | H37: =H34-H36 -> 106733 | I37: =I34-I36 -> 116493.66 | J37: =J34-J36 -> 131049.21 | K37: =K34-K36 -> 147423.44 | L37: =L34-L36 -> 165843.58 | M37: =M34-M36 -> 186565.27
A40: Balance Sheet
A42: Assets
A43: Cash | D43: - | E43: 13931 | F43: 34704 | G43: 18315 | H43: 30242 | I43: =I81 -> 109755.08 | J43: =J81 -> 203481.84 | K43: =K81 -> 313673.09 | L43: =L81 -> 442159.51 | M43: =M81 -> 591033.59
A44: Accounts Receivable | D44: - | E44: 44261 | F44: 48688 | G44: 56924 | H44: 69905 | I44: =((I26/365)*I15) -> 73950.288 | J44: =((J26/365)*J15) -> 83190.167 | K44: =((K26/365)*K15) -> 93584.542 | L44: =((L26/365)*L15) -> 105277.66 | M44: =((M26/365)*M15) -> 118431.81
A45: Inventory | D45: - | E45: 3742 | F45: 2500 | G45: 1246 | H45: 938 | I45: =((I27/365)*I16) -> 3076.8064 | J45: =((J27/365)*J16) -> 3461.2446 | K45: =((K27/365)*K16) -> 3893.7173 | L45: =((L27/365)*L16) -> 4380.2262 | M45: =((M27/365)*M16) -> 4927.523
A46: Property & Equipment | D46: - | E46: 87546 | F46: 109987 | G46: 154552 | H46: 229789 | I46: =I98 -> 236493.57 | J46: =J98 -> 242219.23 | K46: =K98 -> 247108.91 | L46: =L98 -> 251284.66 | M46: =M98 -> 254850.73
A47: Total Assets | D47: - | E47: =SUM(E43,E44,E45,E46) -> 149480 | F47: =SUM(F43,F44,F45,F46) -> 195879 | G47: =SUM(G43,G44,G45,G46) -> 231037 | H47: =SUM(H43,H44,H45,H46) -> 330874 | I47: =SUM(I43:I46) -> 423275.74 | J47: =SUM(J43:J46) -> 532352.48 | K47: =SUM(K43:K46) -> 658260.26 | L47: =SUM(L43:L46) -> 803102.07 | M47: =SUM(M43:M46) -> 969243.65
A49: Liabilities
A50: Accounts Payable | D50: - | E50: 19000 | F50: 18095 | G50: 21996 | H50: 27724 | I50: =((I27/365*I17)) -> 29260.581 | J50: =((J27/365*J17)) -> 32916.607 | K50: =((K27/365*K17)) -> 37029.444 | L50: =((L27/365*L17)) -> 41656.168 | M50: =((M27/365*M17)) -> 46860.988
A51: Debt | D51: - | E51: 61270 | F51: 59965 | G51: 67127 | H51: 60588 | I51: =(H51+I19) -> 55672 | J51: =(I51+J19) -> 50756 | K51: =(J51+K19) -> 45840 | L51: =(K51+L19) -> 40924 | M51: =(L51+M19) -> 36008
...
